<?xml version="1.0" encoding="utf-8"?>
<!-- This URDF was automatically created by SolidWorks to URDF Exporter! Originally created by Stephen Brawner (brawner@gmail.com) 
     Commit Version: 1.6.0-4-g7f85cfe  Build Version: 1.6.7995.38578
     For more information, please see http://wiki.ros.org/sw_urdf_exporter -->
<robot
  name="arm">
  <link
    name="arm_base_footprint">
    <inertial>
      <origin
        xyz="0.0245718759576531 0.0699463467606601 0.0971703622253317"
        rpy="0 0 0" />
      <mass
        value="119.491304287739" />
      <inertia
        ixx="15.3504436258168"
        ixy="-1.83243379729071E-06"
        ixz="3.96596317300498E-07"
        iyy="9.79865788195426"
        iyz="-4.36312632292381"
        izz="19.953186801234" />
    </inertial>
    <visual>
      <origin xyz="0 0 0" rpy="0 0 0" />
      <geometry>
        <mesh
          filename="package://robot_description/meshes/arm_base_footprint.STL" />
      </geometry>
      <material
        name="">
        <color
          rgba="0.792156862745098 0.819607843137255 0.933333333333333 1" />
      </material>
    </visual>
    <collision>
      <origin
        xyz="0 0 0"
        rpy="0 0 0" />
      <geometry>
        <mesh
          filename="package://robot_description/meshes/arm_base_footprint.STL" />
      </geometry>
    </collision>
  </link>
  <link
    name="arm_base">
    <inertial>
      <origin
        xyz="-0.0295481367181956 -7.2596956674463E-05 0.0797519788008734"
        rpy="0 0 0" />
      <mass
        value="3.22741129215856" />
      <inertia
        ixx="0.0149295089781395"
        ixy="1.40113881543758E-05"
        ixz="0.00163251860516278"
        iyy="0.0188400698128559"
        iyz="-1.46497334752122E-07"
        izz="0.0151539463795049" />
    </inertial>
    <visual>
      <origin
        xyz="0 0 0"
        rpy="0 0 0" />
      <geometry>
        <mesh
          filename="package://robot_description/meshes/arm_base.STL" />
      </geometry>
      <material
        name="">
        <color
          rgba="0.796078431372549 0.823529411764706 0.937254901960784 1" />
      </material>
    </visual>
    <collision>
      <origin
        xyz="0 0 0"
        rpy="0 0 0" />
      <geometry>
        <mesh
          filename="package://robot_description/meshes/arm_base.STL" />
      </geometry>
    </collision>
  </link>
  <joint
    name="arm_base_joint"
    type="revolute">
    <origin
      xyz="0.025047 -0.11824 0.13851"
      rpy="0 0 -1.5708" />
    <parent
      link="arm_base_footprint" />
    <child
      link="arm_base" />
    <axis
      xyz="0 0 1" />
    <limit
      lower="-1.57"
      upper="1.57"
      effort="10"
      velocity="10" />
  </joint>
  <link
    name="arm_shoulder">
    <inertial>
      <origin
        xyz="0.207946774744531 0.076200117432586 0.102327743304316"
        rpy="0 0 0" />
      <mass
        value="0.974957548893572" />
      <inertia
        ixx="0.00464714367493188"
        ixy="2.88504045659398E-09"
        ixz="-0.00681141145821841"
        iyy="0.0241635485497036"
        iyz="-1.31218558010455E-12"
        izz="0.0195229574439722" />
    </inertial>
    <visual>
      <origin
        xyz="0 0 0"
        rpy="0 0 0" />
      <geometry>
        <mesh
          filename="package://robot_description/meshes/arm_shoulder.STL" />
      </geometry>
      <material
        name="">
        <color
          rgba="0.866666666666667 0.909803921568627 1 1" />
      </material>
    </visual>
    <collision>
      <origin xyz="0 0 0" rpy="0 0 0" />
      <geometry>
        <mesh
          filename="package://robot_description/meshes/arm_shoulder.STL" />
      </geometry>
    </collision>
  </link>
  <joint
    name="arm_shoulder_joint"
    type="revolute">
    <origin
      xyz="-0.06985 -0.079375 0.22575"
      rpy="0 0 0" />
    <parent
      link="arm_base" />
    <child
      link="arm_shoulder" />
    <axis
      xyz="0 -1 0" />
    <limit
      lower="-1.57"
      upper="0.667"
      effort="10"
      velocity="10" />
  </joint>
  <link
    name="arm_elbow">
    <inertial>
      <origin
        xyz="0.111915739494498 0.0730249586080683 -0.104967246413695"
        rpy="0 0 0" />
      <mass
        value="1.84402735327987" />
      <inertia
        ixx="0.0740795916752292"
        ixy="3.57897826383779E-09"
        ixz="0.0294977280060406"
        iyy="0.0899370275946363"
        iyz="-1.48592172216262E-08"
        izz="0.0158698288504039" />
    </inertial>
    <visual>
      <origin
        xyz="0 0 0"
        rpy="0 0 0" />
      <geometry>
        <mesh
          filename="package://robot_description/meshes/arm_elbow.STL" />
      </geometry>
      <material
        name="">
        <color
          rgba="0.866666666666667 0.909803921568627 1 1" />
      </material>
    </visual>
    <collision>
      <origin
        xyz="0 0 0"
        rpy="0 0 0" />
      <geometry>
        <mesh
          filename="package://robot_description/meshes/arm_elbow.STL" />
      </geometry>
    </collision>
  </link>
  <joint
    name="arm_elbow_joint"
    type="revolute">
    <origin
      xyz="0.42568 0.003175 0.16682"
      rpy="0 0 0" />
    <parent
      link="arm_shoulder" />
    <child
      link="arm_elbow" />
    <axis
      xyz="0 1 0" />
    <limit
      lower="0"
      upper="0.8"
      effort="10"
      velocity="10" />
  </joint>
  <link
    name="arm_wrist">
    <inertial>
      <origin
        xyz="0.00758749942807957 0.0762897289232925 0.00309935288258165"
        rpy="0 0 0" />
      <mass
        value="0.266662965128273" />
      <inertia
        ixx="0.000402488452579321"
        ixy="-3.97836589242259E-07"
        ixz="-9.06656643854072E-06"
        iyy="0.000295655638047142"
        iyz="-2.08931811653999E-07"
        izz="0.000421254175588154" />
    </inertial>
    <visual>
      <origin
        xyz="0 0 0"
        rpy="0 0 0" />
      <geometry>
        <mesh
          filename="package://robot_description/meshes/arm_wrist.STL" />
      </geometry>
      <material
        name="">
        <color
          rgba="0.866666666666667 0.909803921568627 1 1" />
      </material>
    </visual>
    <collision>
      <origin
        xyz="0 0 0"
        rpy="0 0 0" />
      <geometry>
        <mesh
          filename="package://robot_description/meshes/arm_wrist.STL" />
      </geometry>
    </collision>
  </link>
  <joint
    name="arm_wrist_joint"
    type="revolute">
    <origin
      xyz="0.26467 0 -0.4336"
      rpy="0 0 0" />
    <parent
      link="arm_elbow" />
    <child
      link="arm_wrist" />
    <axis
      xyz="0 -1 0" />
    <limit
      lower="-1.57"
      upper="0"
      effort="10"
      velocity="10" />
  </joint>
  <link
    name="gripper">
    <inertial>
      <origin
        xyz="0.12320489633013 0.00538567775138803 -0.00620954234838522"
        rpy="0 0 0" />
      <mass
        value="0.635591580584949" />
      <inertia
        ixx="0.000351925210187695"
        ixy="1.46111614764599E-06"
        ixz="7.38574617353745E-07"
        iyy="0.00105539378215763"
        iyz="-0.000103696525958001"
        izz="0.00110712425743588" />
    </inertial>
    <visual>
      <origin
        xyz="0 0 0"
        rpy="0 0 0" />
      <geometry>
        <mesh
          filename="package://robot_description/meshes/gripper.STL" />
      </geometry>
      <material
        name="">
        <color
          rgba="0.866666666666667 0.909803921568627 1 1" />
      </material>
    </visual>
    <collision>
      <origin
        xyz="0 0 0"
        rpy="0 0 0" />
      <geometry>
        <mesh
          filename="package://robot_description/meshes/gripper.STL" />
      </geometry>
    </collision>
  </link>
  <joint
    name="gripper_joint"
    type="revolute">
    <origin
      xyz="0.0038697 0.074295 0.0022774"
      rpy="0 -0.39004 0" />
    <parent
      link="arm_wrist" />
    <child
      link="gripper" />
    <axis
      xyz="-1 0 0" />
    <limit
      lower="0"
      upper="3.14"
      effort="10"
      velocity="10" />
  </joint>
</robot>
