<?xml version="1.0" encoding="utf-8"?>
<!-- This URDF was automatically created by SolidWorks to URDF Exporter! Originally created by Stephen Brawner (brawner@gmail.com) 
     Commit Version: 1.6.0-4-g7f85cfe  Build Version: 1.6.7995.38578
     For more information, please see http://wiki.ros.org/sw_urdf_exporter -->
<robot
  name="Arm Linkage model">
  <link
    name="base_link">
    <inertial>
      <origin
        xyz="0.327119739334549 -0.385573897694874 0.323575773767598"
        rpy="0 0 0" />
      <mass
        value="3.06342007448754" />
      <inertia
        ixx="0.0160307527911404"
        ixy="9.39840336813469E-10"
        ixz="0.00224509460150349"
        iyy="0.0150959494594248"
        iyz="-1.10471480736458E-09"
        izz="0.0144692423969972" />
    </inertial>
    <visual>
      <origin
        xyz="0 0 0"
        rpy="0 0 0" />
      <geometry>
        <mesh
          filename="package://robot_description/meshes/base_link.STL" />
      </geometry>
      <material
        name="">
        <color
          rgba="0.792156862745098 0.819607843137255 0.933333333333333 1" />
      </material>
    </visual>
    <collision>
      <origin
        xyz="0 0 0"
        rpy="0 0 0" />
      <geometry>
        <mesh
          filename="package://robot_description/meshes/base_link.STL" />
      </geometry>
    </collision>
  </link>
  <link
    name="shoulder">
    <inertial>
      <origin
        xyz="0.143207572859986 -0.0900000000000011 0.138391858217002"
        rpy="0 0 0" />
      <mass
        value="1.46972447540598" />
      <inertia
        ixx="0.00982270362284813"
        ixy="7.8413299435553E-17"
        ixz="-0.0102487828485683"
        iyy="0.0244240913007036"
        iyz="6.00722353436379E-18"
        izz="0.0150390086566239" />
    </inertial>
    <visual>
      <origin
        xyz="0 0 0"
        rpy="0 0 0" />
      <geometry>
        <mesh
          filename="package://robot_description/meshes/shoulder.STL" />
      </geometry>
      <material
        name="">
        <color
          rgba="0.898039215686275 0.917647058823529 0.929411764705882 1" />
      </material>
    </visual>
    <collision>
      <origin
        xyz="0 0 0"
        rpy="0 0 0" />
      <geometry>
        <mesh
          filename="package://robot_description/meshes/shoulder.STL" />
      </geometry>
    </collision>
  </link>
  <joint
    name="shoulder_joint"
    type="revolute">
    <origin
      xyz="0.2958 -0.29557 0.467"
      rpy="0 0 0" />
    <parent
      link="base_link" />
    <child
      link="shoulder" />
    <axis
      xyz="0 1 0" />
    <limit
      lower="-1.57"
      upper="1.57"
      effort="10"
      velocity="10" />
  </joint>
  <link
    name="elbow">
    <inertial>
      <origin
        xyz="0.127323761521914 -0.0900000000000007 0.0200473861405684"
        rpy="0 0 0" />
      <mass
        value="2.29303395925732" />
      <inertia
        ixx="0.010389450850618"
        ixy="1.01659330409391E-16"
        ixz="0.0247496988050138"
        iyy="0.0965408460025389"
        iyz="-8.31922964686182E-18"
        izz="0.0865945491134664" />
    </inertial>
    <visual>
      <origin
        xyz="0 0 0"
        rpy="0 0 0" />
      <geometry>
        <mesh
          filename="package://robot_description/meshes/elbow.STL" />
      </geometry>
      <material
        name="">
        <color
          rgba="0.898039215686275 0.917647058823529 0.929411764705882 1" />
      </material>
    </visual>
    <collision>
      <origin
        xyz="0 0 0"
        rpy="0 0 0" />
      <geometry>
        <mesh
          filename="package://robot_description/meshes/elbow.STL" />
      </geometry>
    </collision>
  </link>
  <joint
    name="elbow_joint"
    type="revolute">
    <origin
      xyz="0.35425 0 0.28903"
      rpy="0 0 0" />
    <parent
      link="shoulder" />
    <child
      link="elbow" />
    <axis
      xyz="0 1 0" />
    <limit
      lower="-1.57"
      upper="1.57"
      effort="10"
      velocity="10" />
  </joint>
  <link
    name="wrist">
    <inertial>
      <origin
        xyz="0.00272603728020782 -0.0931117435140996 -4.76166492902053E-07"
        rpy="0 0 0" />
      <mass
        value="0.907669054556265" />
      <inertia
        ixx="0.00111675391373477"
        ixy="-8.57603201835166E-06"
        ixz="-5.09853554761219E-08"
        iyy="0.00181392448184218"
        iyz="-3.66568455479822E-08"
        izz="0.00214126667857085" />
    </inertial>
    <visual>
      <origin
        xyz="0 0 0"
        rpy="0 0 0" />
      <geometry>
        <mesh
          filename="package://robot_description/meshes/wrist.STL" />
      </geometry>
      <material
        name="">
        <color
          rgba="0.792156862745098 0.819607843137255 0.933333333333333 1" />
      </material>
    </visual>
    <collision>
      <origin
        xyz="0 0 0"
        rpy="0 0 0" />
      <geometry>
        <mesh
          filename="package://robot_description/meshes/wrist.STL" />
      </geometry>
    </collision>
  </link>
  <joint
    name="wrist_joint"
    type="revolute">
    <origin
      xyz="0.50432 0 -0.061042"
      rpy="-3.1416 1.4178 -3.1416" />
    <parent
      link="elbow" />
    <child
      link="wrist" />
    <axis
      xyz="0 1 0" />
    <limit
      lower="-1.54"
      upper="1.54"
      effort="10"
      velocity="10" />
  </joint>
  <link
    name="wrist_rotate">
    <inertial>
      <origin
        xyz="0.162432716240768 -0.00270052335930604 7.66993540740057E-05"
        rpy="0 0 0" />
      <mass
        value="4.26992312903956" />
      <inertia
        ixx="0.00797359273906145"
        ixy="0.000342360688549404"
        ixz="-9.26419011758301E-06"
        iyy="0.0226639487434173"
        iyz="-0.000152701592992127"
        izz="0.0170263898069213" />
    </inertial>
    <visual>
      <origin
        xyz="0 0 0"
        rpy="0 0 0" />
      <geometry>
        <mesh
          filename="package://robot_description/meshes/wrist_rotate.STL" />
      </geometry>
      <material
        name="">
        <color
          rgba="0.898039215686275 0.917647058823529 0.929411764705882 1" />
      </material>
    </visual>
    <collision>
      <origin
        xyz="0 0 0"
        rpy="0 0 0" />
      <geometry>
        <mesh
          filename="package://robot_description/meshes/wrist_rotate.STL" />
      </geometry>
    </collision>
  </link>
  <joint
    name="wrist_rotate_joint"
    type="revolute">
    <origin
      xyz="0.063978 -0.09 0"
      rpy="-1.5708 0 0" />
    <parent
      link="wrist" />
    <child
      link="wrist_rotate" />
    <axis
      xyz="1 0 0" />
    <limit
      lower="-3.14"
      upper="3.14"
      effort="10"
      velocity="10" />
  </joint>
</robot>