<?xml version="1.0" encoding="utf-8"?>
<!-- This URDF was automatically created by SolidWorks to URDF Exporter! Originally created by Stephen Brawner (brawner@gmail.com) 
     Commit Version: 1.6.0-4-g7f85cfe  Build Version: 1.6.7995.38578
     For more information, please see http://wiki.ros.org/sw_urdf_exporter -->
<robot
  name="arm_urdf">
  <link
    name="base_link">
    <inertial>
      <origin
        xyz="0.327119739334549 0.323575773767598 0.385573897694874"
        rpy="0 0 0" />
      <mass
        value="3.06342007448754" />
      <inertia
        ixx="0.0160307527911404"
        ixy="0.00224509460150349"
        ixz="-9.39840337126236E-10"
        iyy="0.0144692423969972"
        iyz="1.10471480676346E-09"
        izz="0.0150959494594247" />
    </inertial>
    <visual>
      <origin
        xyz="0 0 0"
        rpy="0 0 0" />
      <geometry>
        <mesh
          filename="package://robot_description/meshes/base_link.STL" />
      </geometry>
      <material
        name="">
        <color
          rgba="0.792156862745098 0.819607843137255 0.933333333333333 1" />
      </material>
    </visual>
    <collision>
      <origin
        xyz="0 0 0"
        rpy="0 0 0" />
      <geometry>
        <mesh
          filename="package://robot_description/meshes/base_link.STL" />
      </geometry>
    </collision>
  </link>
  <link
    name="shoulder">
    <inertial>
      <origin
        xyz="0.198448782625764 0.0166971859771411 0.0900000000000011"
        rpy="0 0 0" />
      <mass
        value="1.46972447540598" />
      <inertia
        ixx="0.00186714741587092"
        ixy="0.000498063676444094"
        ixz="-6.45634689426696E-17"
        iyy="0.0229945648636011"
        iyz="4.49210971843479E-17"
        izz="0.0244240913007036" />
    </inertial>
    <visual>
      <origin
        xyz="0 0 0"
        rpy="0 0 0" />
      <geometry>
        <mesh
          filename="package://robot_description/meshes/shoulder.STL" />
      </geometry>
      <material
        name="">
        <color
          rgba="0.898039215686275 0.917647058823529 0.929411764705882 1" />
      </material>
    </visual>
    <collision>
      <origin
        xyz="0 0 0"
        rpy="0 0 0" />
      <geometry>
        <mesh
          filename="package://robot_description/meshes/shoulder.STL" />
      </geometry>
    </collision>
  </link>
  <joint
    name="shoulder_joint"
    type="revolute">
    <origin
      xyz="0.2958 -0.29557 0.467"
      rpy="1.5708 -0.68436 0" />
    <parent
      link="base_link" />
    <child
      link="shoulder" />
    <axis
      xyz="0 1 0" />
    <limit
      lower="-1.57"
      upper="1.57"
      effort="10"
      velocity="10" />
  </joint>
  <link
    name="elbow">
    <inertial>
      <origin
        xyz="0.123992328843944 0.0352014250707769 0.0900000000000007"
        rpy="0 0 0" />
      <mass
        value="2.29303395925732" />
      <inertia
        ixx="0.00558496330938212"
        ixy="0.0149444988280807"
        ixz="-1.01887144964319E-16"
        iyy="0.0913990366547023"
        iyz="-3.92497568145118E-18"
        izz="0.0965408460025389" />
    </inertial>
    <visual>
      <origin
        xyz="0 0 0"
        rpy="0 0 0" />
      <geometry>
        <mesh
          filename="package://robot_description/meshes/elbow.STL" />
      </geometry>
      <material
        name="">
        <color
          rgba="0.898039215686275 0.917647058823529 0.929411764705882 1" />
      </material>
    </visual>
    <collision>
      <origin
        xyz="0 0 0"
        rpy="0 0 0" />
      <geometry>
        <mesh
          filename="package://robot_description/meshes/elbow.STL" />
      </geometry>
    </collision>
  </link>
  <joint
    name="elbow_joint"
    type="revolute">
    <origin
      xyz="0.4572 0 0"
      rpy="0 0 -0.80481" />
    <parent
      link="shoulder" />
    <child
      link="elbow" />
    <axis
      xyz="0 1 0" />
    <limit
      lower="-1.57"
      upper="1.57"
      effort="10"
      velocity="10" />
  </joint>
  <link
    name="wrist">
    <inertial>
      <origin
        xyz="-0.0931117435140994 -0.00269413352116665 -0.000415841375938975"
        rpy="0 0 0" />
      <mass
        value="0.907669054556265" />
      <inertia
        ixx="0.00181392448184218"
        ixy="8.48147746070204E-06"
        ixz="1.27051524496893E-06"
        iyy="0.00114052478993438"
        iyz="-0.000154235255833583"
        izz="0.00211749580237124" />
    </inertial>
    <visual>
      <origin
        xyz="0 0 0"
        rpy="0 0 0" />
      <geometry>
        <mesh
          filename="package://robot_description/meshes/wrist.STL" />
      </geometry>
      <material
        name="">
        <color
          rgba="0.792156862745098 0.819607843137255 0.933333333333333 1" />
      </material>
    </visual>
    <collision>
      <origin
        xyz="0 0 0"
        rpy="0 0 0" />
      <geometry>
        <mesh
          filename="package://robot_description/meshes/wrist.STL" />
      </geometry>
    </collision>
  </link>
  <joint
    name="wrist_joint"
    type="revolute">
    <origin
      xyz="0.508 0 0"
      rpy="0.12045 1.5708 0" />
    <parent
      link="elbow" />
    <child
      link="wrist" />
    <axis
      xyz="0 1 0" />
    <limit
      lower="-1.54"
      upper="1.54"
      effort="10"
      velocity="10" />
  </joint>
  <link
    name="wrist_rotate">
    <inertial>
      <origin
        xyz="-0.162432716240767 -0.00270160992938751 -3.60479018712834E-06"
        rpy="0 0 0" />
      <mass
        value="4.26992312903956" />
      <inertia
        ixx="0.00797359273906144"
        ixy="-0.00034248600887847"
        ixz="2.25482237874336E-09"
        iyy="0.0226680818609778"
        iyz="1.7206221845532E-09"
        izz="0.0170222566893608" />
    </inertial>
    <visual>
      <origin
        xyz="0 0 0"
        rpy="0 0 0" />
      <geometry>
        <mesh
          filename="package://robot_description/meshes/wrist_rotate.STL" />
      </geometry>
      <material
        name="">
        <color
          rgba="0.898039215686275 0.917647058823529 0.929411764705882 1" />
      </material>
    </visual>
    <collision>
      <origin
        xyz="0 0 0"
        rpy="0 0 0" />
      <geometry>
        <mesh
          filename="package://robot_description/meshes/wrist_rotate.STL" />
      </geometry>
    </collision>
  </link>
  <joint
    name="wrist_rotate_joint"
    type="revolute">
    <origin
      xyz="-0.09 -0.063231 -0.0097485"
      rpy="-1.5437 -0.15297 1.5708" />
    <parent
      link="wrist" />
    <child
      link="wrist_rotate" />
    <axis
      xyz="1 0 0" />
    <limit
      lower="-3.14"
      upper="3.14"
      effort="10"
      velocity="10" />
  </joint>
</robot>