<?xml version="1.0" encoding="utf-8"?>
<!-- This URDF was automatically created by SolidWorks to URDF Exporter! Originally created by Stephen Brawner (brawner@gmail.com) 
     Commit Version: 1.6.0-4-g7f85cfe  Build Version: 1.6.7995.38578
     For more information, please see http://wiki.ros.org/sw_urdf_exporter -->
<robot
  name="robot_description">
  <link
    name="arm_base_footprint">
    <inertial>
      <origin
        xyz="0.0245718759576531 0.0971703622253317 -0.0699463467606601"
        rpy="0 0 0" />
      <mass
        value="119.491304287739" />
      <inertia
        ixx="15.3504436258168"
        ixy="3.96596317291848E-07"
        ixz="1.83243379728635E-06"
        iyy="19.953186801234"
        iyz="4.36312632292381"
        izz="9.79865788195426" />
    </inertial>
    <visual>
      <origin
        xyz="0 0 0"
        rpy="0 0 0" />
      <geometry>
        <mesh
          filename="package://robot_description/meshes/arm_base_footprint.STL" />
      </geometry>
      <material
        name="">
        <color
          rgba="0.792156862745098 0.819607843137255 0.933333333333333 1" />
      </material>
    </visual>
    <collision>
      <origin
        xyz="0 0 0"
        rpy="0 0 0" />
      <geometry>
        <mesh
          filename="package://robot_description/meshes/arm_base_footprint.STL" />
      </geometry>
    </collision>
  </link>
  <link
    name="arm_base">
    <inertial>
      <origin
        xyz="0.00139266117755199 0.0295153883369309 0.0797519788008734"
        rpy="0 0 0" />
      <mass
        value="3.22741129215856" />
      <inertia
        ixx="0.0188290668811091"
        ixy="-0.000207612351384155"
        ixz="-8.10961041746693E-05"
        iyy="0.0149405119098863"
        iyz="-0.0016305031246679"
        izz="0.0151539463795049" />
    </inertial>
    <visual>
      <origin
        xyz="0 0 0"
        rpy="0 0 0" />
      <geometry>
        <mesh
          filename="package://robot_description/meshes/arm_base.STL" />
      </geometry>
      <material
        name="">
        <color
          rgba="0.796078431372549 0.823529411764706 0.937254901960784 1" />
      </material>
    </visual>
    <collision>
      <origin
        xyz="0 0 0"
        rpy="0 0 0" />
      <geometry>
        <mesh
          filename="package://robot_description/meshes/arm_base.STL" />
      </geometry>
    </collision>
  </link>
  <joint
    name="arm_base_joint"
    type="revolute">
    <origin
      xyz="0.025047 -0.11824 0.13851"
      rpy="0 0 0.049606" />
    <parent
      link="arm_base_footprint" />
    <child
      link="arm_base" />
    <axis
      xyz="0 0 1" />
    <limit
      lower="-3.14"
      upper="3.14"
      effort="10"
      velocity="10" />
  </joint>
  <link
    name="arm_shoulder">
    <inertial>
      <origin
        xyz="0.0484529280588457 -0.076199882567414 -0.0193978900454077"
        rpy="0 0 0" />
      <mass
        value="0.974957548893572" />
      <inertia
        ixx="0.0019996818638543"
        ixy="-2.6856548951694E-09"
        ixz="5.58851482820311E-05"
        iyy="0.0241635485497036"
        iyz="1.05390600085211E-09"
        izz="0.0221704192550498" />
    </inertial>
    <visual>
      <origin
        xyz="0 0 0"
        rpy="0 0 0" />
      <geometry>
        <mesh
          filename="package://robot_description/meshes/arm_shoulder.STL" />
      </geometry>
      <material
        name="">
        <color
          rgba="0.898039215686275 0.917647058823529 0.929411764705882 1" />
      </material>
    </visual>
    <collision>
      <origin
        xyz="0 0 0"
        rpy="0 0 0" />
      <geometry>
        <mesh
          filename="package://robot_description/meshes/arm_shoulder.STL" />
      </geometry>
    </collision>
  </link>
  <joint
    name="arm_shoulder_joint"
    type="revolute">
    <origin
      xyz="0.0635 -0.19367 0.3277"
      rpy="3.1416 0.3735 1.5212" />
    <parent
      link="arm_base" />
    <child
      link="arm_shoulder" />
    <axis
      xyz="0 1 0" />
    <limit
      lower="-1.57"
      upper="1.57"
      effort="10"
      velocity="10" />
  </joint>
  <link
    name="arm_elbow">
    <inertial>
      <origin
        xyz="-0.1060959449046 0.0408368222638692 0.0698500413919339"
        rpy="0 0 0" />
      <mass
        value="1.84402735327987" />
      <inertia
        ixx="0.00543516703844774"
        ixy="0.0124030077463986"
        ixz="-1.45477801304255E-08"
        iyy="0.0845142534871854"
        iyz="4.68695576828311E-09"
        izz="0.0899370275946364" />
    </inertial>
    <visual>
      <origin
        xyz="0 0 0"
        rpy="0 0 0" />
      <geometry>
        <mesh
          filename="package://robot_description/meshes/arm_elbow.STL" />
      </geometry>
      <material
        name="">
        <color
          rgba="0.898039215686275 0.917647058823529 0.929411764705882 1" />
      </material>
    </visual>
    <collision>
      <origin
        xyz="0 0 0"
        rpy="0 0 0" />
      <geometry>
        <mesh
          filename="package://robot_description/meshes/arm_elbow.STL" />
      </geometry>
    </collision>
  </link>
  <joint
    name="arm_elbow_joint"
    type="revolute">
    <origin
      xyz="-0.22191 -0.00635 0.25014"
      rpy="-1.5708 -1.3963 3.1416" />
    <parent
      link="arm_shoulder" />
    <child
      link="arm_elbow" />
    <axis
      xyz="0 1 0" />
    <limit
      lower="-1.57"
      upper="1.57"
      effort="10"
      velocity="10" />
  </joint>
  <link
    name="arm_wrist">
    <inertial>
      <origin
        xyz="0.00452642086525723 -0.0341652481567961 0.0380102710767077"
        rpy="0 0 0" />
      <mass
        value="0.266662965128272" />
      <inertia
        ixx="0.000424918034348284"
        ixy="-1.542962546561E-07"
        ixz="4.19717565955253E-08"
        iyy="0.00039882459381919"
        iyz="-4.47397837846059E-07"
        izz="0.000295655638047142" />
    </inertial>
    <visual>
      <origin
        xyz="0 0 0"
        rpy="0 0 0" />
      <geometry>
        <mesh
          filename="package://robot_description/meshes/arm_wrist.STL" />
      </geometry>
      <material
        name="">
        <color
          rgba="0.898039215686275 0.917647058823529 0.929411764705882 1" />
      </material>
    </visual>
    <collision>
      <origin
        xyz="0 0 0"
        rpy="0 0 0" />
      <geometry>
        <mesh
          filename="package://robot_description/meshes/arm_wrist.STL" />
      </geometry>
    </collision>
  </link>
  <joint
    name="arm_wrist_joint"
    type="revolute">
    <origin
      xyz="0.2358 -0.019078 0.028575"
      rpy="0 0 2.2066" />
    <parent
      link="arm_elbow" />
    <child
      link="arm_wrist" />
    <axis
      xyz="0 1 0" />
    <limit
      lower="-1.57"
      upper="1.57"
      effort="10"
      velocity="10" />
  </joint>
  <link
    name="gripper">
    <inertial>
      <origin
        xyz="-0.0776681189833697 0.0081921997027346 -0.00504119866871313"
        rpy="0 0 0" />
      <mass
        value="0.635591580584878" />
      <inertia
        ixx="0.000351925210187597"
        ixy="-3.1754818227097E-07"
        ixz="1.6060871751641E-06"
        iyy="0.00118813268308321"
        iyz="1.04694135391267E-08"
        izz="0.000974385356510224" />
    </inertial>
    <visual>
      <origin
        xyz="0 0 0"
        rpy="0 0 0" />
      <geometry>
        <mesh
          filename="package://robot_description/meshes/gripper.STL" />
      </geometry>
      <material
        name="">
        <color
          rgba="0.898039215686275 0.917647058823529 0.929411764705882 1" />
      </material>
    </visual>
    <collision>
      <origin
        xyz="0 0 0"
        rpy="0 0 0" />
      <geometry>
        <mesh
          filename="package://robot_description/meshes/gripper.STL" />
      </geometry>
    </collision>
  </link>
  <joint
    name="gripper joint"
    type="revolute">
    <origin
      xyz="0.0051746 -0.075951 0.035385"
      rpy="-3.1368 0 1.5708" />
    <parent
      link="arm_wrist" />
    <child
      link="gripper" />
    <axis
      xyz="1 0 0" />
    <limit
      lower="-1.57"
      upper="1.57"
      effort="10"
      velocity="10" />
  </joint>
</robot>